{"uuid": "0100b15f-b2ec-4a4f-bb21-79d7860a562b", "children": ["e9e50a71-d295-40bc-87cb-0f5f4b129ce4"], "befores": [{"name": "open_url", "status": "broken", "statusDetails": {"message": "urllib3.exceptions.MaxRetryError: HTTPConnectionPool(host='127.0.0.1', port=14233): Max retries exceeded with url: /session/36a2a6933c874cebaeacf7786b334b5b/timeouts (Caused by NewConnectionError('<urllib3.connection.HTTPConnection object at 0x0000023B8EE51700>: Failed to establish a new connection: [WinError 10061] 由于目标计算机积极拒绝，无法连接。'))\n", "trace": "  File \"c:\\users\\123\\appdata\\local\\programs\\python\\python39\\lib\\site-packages\\pluggy\\callers.py\", line 187, in _multicall\n    res = hook_impl.function(*args)\n  File \"c:\\users\\123\\appdata\\local\\programs\\python\\python39\\lib\\site-packages\\_pytest\\fixtures.py\", line 1126, in pytest_fixture_setup\n    result = call_fixture_func(fixturefunc, request, kwargs)\n  File \"c:\\users\\123\\appdata\\local\\programs\\python\\python39\\lib\\site-packages\\_pytest\\fixtures.py\", line 932, in call_fixture_func\n    fixture_result = fixturefunc(**kwargs)\n  File \"D:\\auto_test_iMyMac\\PycharmProjects\\pytest_project\\TestCase\\store_test_case\\test_buy_option.py\", line 18, in open_url\n  File \"D:\\auto_test_iMyMac\\pytest_project\\page\\basepage.py\", line 28, in get_url\n    self.driver.set_page_load_timeout(300)\n  File \"c:\\users\\123\\appdata\\local\\programs\\python\\python39\\lib\\site-packages\\selenium\\webdriver\\remote\\webdriver.py\", line 947, in set_page_load_timeout\n    self.execute(Command.SET_TIMEOUTS, {\n  File \"c:\\users\\123\\appdata\\local\\programs\\python\\python39\\lib\\site-packages\\selenium\\webdriver\\remote\\webdriver.py\", line 319, in execute\n    response = self.command_executor.execute(driver_command, params)\n  File \"c:\\users\\123\\appdata\\local\\programs\\python\\python39\\lib\\site-packages\\selenium\\webdriver\\remote\\remote_connection.py\", line 374, in execute\n    return self._request(command_info[0], url, body=data)\n  File \"c:\\users\\123\\appdata\\local\\programs\\python\\python39\\lib\\site-packages\\selenium\\webdriver\\remote\\remote_connection.py\", line 397, in _request\n    resp = self._conn.request(method, url, body=body, headers=headers)\n  File \"c:\\users\\123\\appdata\\local\\programs\\python\\python39\\lib\\site-packages\\urllib3\\request.py\", line 78, in request\n    return self.request_encode_body(\n  File \"c:\\users\\123\\appdata\\local\\programs\\python\\python39\\lib\\site-packages\\urllib3\\request.py\", line 170, in request_encode_body\n    return self.urlopen(method, url, **extra_kw)\n  File \"c:\\users\\123\\appdata\\local\\programs\\python\\python39\\lib\\site-packages\\urllib3\\poolmanager.py\", line 375, in urlopen\n    response = conn.urlopen(method, u.request_uri, **kw)\n  File \"c:\\users\\123\\appdata\\local\\programs\\python\\python39\\lib\\site-packages\\urllib3\\connectionpool.py\", line 783, in urlopen\n    return self.urlopen(\n  File \"c:\\users\\123\\appdata\\local\\programs\\python\\python39\\lib\\site-packages\\urllib3\\connectionpool.py\", line 783, in urlopen\n    return self.urlopen(\n  File \"c:\\users\\123\\appdata\\local\\programs\\python\\python39\\lib\\site-packages\\urllib3\\connectionpool.py\", line 783, in urlopen\n    return self.urlopen(\n  File \"c:\\users\\123\\appdata\\local\\programs\\python\\python39\\lib\\site-packages\\urllib3\\connectionpool.py\", line 755, in urlopen\n    retries = retries.increment(\n  File \"c:\\users\\123\\appdata\\local\\programs\\python\\python39\\lib\\site-packages\\urllib3\\util\\retry.py\", line 574, in increment\n    raise MaxRetryError(_pool, url, error or ResponseError(cause))\n"}, "start": 1637223469910, "stop": 1637223478077}], "start": 1637223469910, "stop": 1637223478191}